Workbook

Sheet Master
A1: publication_id | B1: year | C1: date | D1: title | E1: authors | F1: pang_faculty_authors | G1: document_type | H1: source_title | I1: tertiary_title | J1: publisher | K1: place_published | L1: volume | M1: issue | N1: pages | O1: doi | P1: doi_normalized | Q1: issn | R1: isbn | S1: url | T1: abstract | U1: language | V1: source | W1: legacy_nid | X1: legacy_status | Y1: include_in_master | Z1: data_quality_flags | AA1: scopus_eid | AB1: verification_status | AC1: verification_source_url
A2: scopus-10-1109-taes-2025-3619912 | B2: 2026 | D2: A Split Pulse Fusion Method for Radar Reconnaissance | E2: Ronghua Guo; Yang-Yang Dong; Dan Bao; Chunxi Dong; Sergio Vitale; Giampaolo Ferraioli; Vito Pascazio; Wenbo Li; Zhiyuan Li | F2: Giampaolo Ferraioli | G2: Journal Article | H2: IEEE Transactions on Aerospace and Electronic Systems | L2: 62 | N2: 217-233 | O2: 10.1109/TAES.2025.3619912 | P2: 10.1109/taes.2025.3619912 | S2: https://doi.org/10.1109/TAES.2025.3619912 | V2: scopus | Y2: yes | AB2: verified_scopus | AC2: https://www.sciencedirect.com/author/7003486376/vito-pascazio
A3: scopus-10-3390-automation7020036 | B3: 2026 | C3: 2026-02-25 | D3: Intelligent Tomato Leaf Disease Detection and Automated Spray Prescription Using YOLOv9: A Smart Agriculture Approach | E3: Shahab Ul Islam; Giampaolo Ferraioli; Ghassan Husnain; Abdul Waheed; Vito Pascazio | F3: Giampaolo Ferraioli | G3: Journal Article | H3: Automation | L3: 7 | M3: 2 | N3: 36 | O3: 10.3390/automation7020036 | P3: 10.3390/automation7020036 | S3: https://doi.org/10.3390/automation7020036 | V3: scopus | Y3: yes | AB3: verified_scopus | AC3: https://www.sciencedirect.com/author/7003486376/vito-pascazio
A4: scopus-10-1016-j-oceaneng-2025-123471 | B4: 2026 | C4: 2026-01-15 | D4: Sea state reconstruction based on the Spearman rank correlation using full-scale data from a containership | E4: Silvia Ascione; Ulrik D. Nielsen; Vincenzo Piscopo; Gaute Storhaug | F4: Vincenzo Piscopo | G4: Journal Article | H4: Ocean Engineering | L4: 343 | M4: Part 4 | N4: 123471 | O4: 10.1016/j.oceaneng.2025.123471 | P4: 10.1016/j.oceaneng.2025.123471 | S4: https://doi.org/10.1016/j.oceaneng.2025.123471 | V4: scopus | Y4: yes | AB4: verified_scopus | AC4: https://www.sciencedirect.com/author/57224792997/ulrik-dam-nielsen
A5: scopus-10-1109-lgrs-2026-3659009 | B5: 2026 | D5: Sentinel-1 Ground Truth Dataset for Coastline Extraction | E5: Gianpaolo Passarello; Sergio Vitale; Giampaolo Ferraioli; Vito Pascazio | F5: Giampaolo Ferraioli | G5: Journal Article | H5: IEEE Geoscience and Remote Sensing Letters | L5: 23 | O5: 10.1109/LGRS.2026.3659009 | P5: 10.1109/lgrs.2026.3659009 | S5: https://doi.org/10.1109/LGRS.2026.3659009 | V5: scopus | Y5: yes | AB5: verified_scopus | AC5: https://www.sciencedirect.com/author/7003486376/vito-pascazio
A6: scopus-10-1109-lgrs-2025-3555441 | B6: 2025 | D6: A Deep Learning Solution for Phase Screen Estimation in SAR Tomography | E6: Hossein Aghababaei; Giampaolo Ferraioli; Sergio Vitale; Alfred Stein | F6: Giampaolo Ferraioli | G6: Journal Article | H6: IEEE Geoscience and Remote Sensing Letters | L6: 22 | N6: 4007605 | O6: 10.1109/LGRS.2025.3555441 | P6: 10.1109/lgrs.2025.3555441 | S6: https://doi.org/10.1109/LGRS.2025.3555441 | V6: scopus | Y6: yes | AB6: verified_scopus_indirect | AC6: https://research.utwente.nl/en/publications/a-deep-learning-solution-for-phase-screen-estimation-in-sar-tomog/
A7: scopus-10-1109-metroaerospace64938-2025-11114485 | B7: 2025 | D7: A Micro Radar-Based Low-Cost Solution for Positioning and Detection, and Avoidance System | E7: Gennaro Ariante; Lucie Rocquelain; Salvatore Gaglione; Silvio Del Pizzo; Giuseppe Del Core | F7: Salvatore Gaglione; Silvio Del Pizzo | G7: Conference Paper | H7: 2025 IEEE International Workshop on Metrology for AeroSpace, MetroAeroSpace 2025 - Proceedings | O7: 10.1109/MetroAeroSpace64938.2025.11114485 | P7: 10.1109/metroaerospace64938.2025.11114485 | S7: https://www.scopus.com/inward/record.uri?eid=2-s2.0-105015377060&doi=10.1109%2fMetroAeroSpace64938.2025.11114485&partnerID=40&md5=03287e527efef9f4adf9d23e9c84507f | V7: scopus | Y7: yes | AA7: 2-s2.0-105015377060 | AB7: verified_scopus | AC7: https://www.scopus.com/inward/record.uri?eid=2-s2.0-105015377060&doi=10.1109%2fMetroAeroSpace64938.2025.11114485&partnerID=40&md5=03287e527efef9f4adf9d23e9c84507f
A8: scopus-10-1016-j-oceaneng-2025-121579 | B8: 2025 | D8: A numerical model of ship manoeuvring for the KVLCC2 hull, in regular and long-crested irregular waves | E8: Maria Acanfora; Marco Altosole; Silvia Pennino | F8: Silvia Pennino | G8: Journal Article | H8: Ocean Engineering | L8: 333 | N8: 121579 | O8: 10.1016/j.oceaneng.2025.121579 | P8: 10.1016/j.oceaneng.2025.121579 | S8: https://doi.org/10.1016/j.oceaneng.2025.121579 | V8: scopus | Y8: yes | AB8: verified_scopus | AC8: https://ouci.dntb.gov.ua/works/9Gmm8Yyx/
A9: scopus-10-1109-metrosea66681-2025-11245754 | B9: 2025 | D9: Advancing Offshore Renewable Energy in the Mediterranean Sea: Digital-Med, a Project for Integrating Resource Assessment and Decision Support | E9: Silvio Del Pizzo; Salvatore Gaglione; Pier Paolo Amoroso; Pasquale Contestabile; Yuri Cotroneo; Francesco Giuseppe Figliomeni; Diego Vicinanza; Giorgio Budillon | F9: Silvio Del Pizzo; Salvatore Gaglione | G9: Conference Paper | H9: 2025 IEEE International Workshop on Metrology for the Sea; Learning to Measure Sea Health Parameters, MetroSea 2025 - Proceedings | O9: 10.1109/MetroSea66681.2025.11245754 | P9: 10.1109/metrosea66681.2025.11245754 | S9: https://www.scopus.com/inward/record.uri?eid=2-s2.0-105029542122&doi=10.1109%2fMetroSea66681.2025.11245754&partnerID=40&md5=deea9b4f945a9ec20267bce45c30d977 | V9: scopus | Y9: yes | AA9: 2-s2.0-105029542122 | AB9: verified_scopus | AC9: https://www.scopus.com/inward/record.uri?eid=2-s2.0-105029542122&doi=10.1109%2fMetroSea66681.2025.11245754&partnerID=40&md5=deea9b4f945a9ec20267bce45c30d977
A10: scopus-10-1109-igarss55030-2025-11243038 | B10: 2025 | C10: 2025-08 | D10: An Open-Access Cross-Modal Forest Benchmark Training Dataset With Sentinel-1 and Lidar data | E10: Hossein Aghababaei; Giampaolo Ferraioli; Gilda Schirinzi; Erkki Tomppo; Jaan Praks | F10: Giampaolo Ferraioli | G10: Conference Paper | H10: IGARSS 2025 - 2025 IEEE International Geoscience and Remote Sensing Symposium | N10: 3588-3591 | O10: 10.1109/IGARSS55030.2025.11243038 | P10: 10.1109/igarss55030.2025.11243038 | S10: https://www.scopus.com/pages/publications/105034117757 | V10: scopus | Y10: yes | AA10: 2-s2.0-105034117757 | AB10: verified_scopus | AC10: https://research.aalto.fi/en/publications/an-open-access-cross-modal-forest-benchmark-training-dataset-with/
A11: scopus-10-1016-j-oceaneng-2025-122258 | B11: 2025 | C11: 2025-11-30 | D11: Assessment of bimodal sea states by the wave buoy analogy method | E11: Vincenzo Piscopo; Silvia Ascione; Antonio Scamardella | F11: Vincenzo Piscopo; Antonio Scamardella | G11: Journal Article | H11: Ocean Engineering | L11: 340 | M11: Part 1 | N11: 122258 | O11: 10.1016/j.oceaneng.2025.122258 | P11: 10.1016/j.oceaneng.2025.122258 | S11: https://doi.org/10.1016/j.oceaneng.2025.122258 | V11: scopus | Y11: yes | AB11: verified_scopus | AC11: https://www.sciencedirect.com/author/6507257720/v-piscopo
A12: scopus-10-1038-s41598-025-00653-8 | B12: 2025 | C12: 2025-05-12 | D12: Augustus’ solar meridian functioning and the birth of the western leap year | E12: V. Baiocchi; M. Baumgartner; M. Barbarella; M. T. D’Alessio; Silvio Del Pizzo; F. Giannone; F. Radicioni; A. Stoppini; G. Tosi; Salvatore Troisi; L. Alessandri | F12: Silvio Del Pizzo; Salvatore Troisi | G12: Journal Article | H12: Scientific Reports | L12: 15 | N12: 16463 | O12: 10.1038/s41598-025-00653-8 | P12: 10.1038/s41598-025-00653-8 | S12: https://doi.org/10.1038/s41598-025-00653-8 | V12: scopus | Y12: yes | AB12: verified_scopus_indirect | AC12: https://research.rug.nl/en/publications/augustus-solar-meridian-functioning-and-the-birth-of-the-western-/
A13: scopus-10-1109-mgrs-2025-3612752 | B13: 2025 | C13: 2025-12-17 | D13: IEEE Geoscience and Remote Sensing Society Awards Presented at the IEEE International Geoscience and Remote Sensing Symposium 2025 Awards Reception and Ceremony | E13: Francesca Bovolo; Jaya Sreevalsan-Nair; Antonio Plaza; Alberto Moreira; Giampaolo Ferraioli; Claudio Persello | F13: Giampaolo Ferraioli | G13: Conference Report | H13: IEEE Geoscience and Remote Sensing Magazine | L13: 13 | N13: 444-454 | O13: 10.1109/MGRS.2025.3612752 | P13: 10.1109/mgrs.2025.3612752 | S13: https://doi.org/10.1109/MGRS.2025.3612752 | V13: scopus | Y13: yes | AB13: verified_scopus | AC13: https://elib.dlr.de/222017/
A14: scopus-10-1109-mgrs-2025-3599367 | B14: 2025 | C14: 2025-12 | D14: IGARSS 2025 in Brisbane, Australia: Impressions of the First Days | E14: Alberto Moreira; Francesca Bovolo; Jaya Sreevalsan-Nair; Giampaolo Ferraioli | F14: Giampaolo Ferraioli | G14: Conference Report | H14: IEEE Geoscience and Remote Sensing Magazine | L14: 13 | M14: 4 | N14: 430-443 | O14: 10.1109/MGRS.2025.3599367 | P14: 10.1109/mgrs.2025.3599367 | S14: https://doi.org/10.1109/MGRS.2025.3599367 | V14: scopus | Y14: yes | AB14: verified_scopus | AC14: https://elib.dlr.de/218787/
A15: scopus-10-33012-2025-19984 | B15: 2025 | D15: The G4 Solar Storm of May 2024: Impact on the GNSS carrier-phase measurements | E15: Giovanni Cappello; Ciro Gioia; Antonio Angrisano; Gabriele Portelli; Salvatore Gaglione | F15: Salvatore Gaglione | G15: Conference Paper | H15: Proceedings of the International Technical Meeting of The Institute of Navigation, ITM | O15: 10.33012/2025.19984 | P15: 10.33012/2025.19984 | S15: https://www.scopus.com/inward/record.uri?eid=2-s2.0-105001675036&doi=10.33012%2f2025.19984&partnerID=40&md5=739f848160bb42247f9941f85f76ae90 | V15: scopus | Y15: yes | AA15: 2-s2.0-105001675036 | AB15: verified_scopus | AC15: https://www.scopus.com/inward/record.uri?eid=2-s2.0-105001675036&doi=10.33012%2f2025.19984&partnerID=40&md5=739f848160bb42247f9941f85f76ae90
A16: scopus-10-1109-metroaerospace64938-2025-11114637 | B16: 2025 | D16: The Galileo-based UAV velocity: Doppler and Time-Differenced Carrier Phase | E16: Giovanni Cappello; Ciro Gioia; Andrea Piccolo; Antonio Angrisano; Salvatore Gaglione | F16: Salvatore Gaglione | G16: Conference Paper | H16: 2025 IEEE International Workshop on Metrology for AeroSpace, MetroAeroSpace 2025 - Proceedings | O16: 10.1109/MetroAeroSpace64938.2025.11114637 | P16: 10.1109/metroaerospace64938.2025.11114637 | S16: https://www.scopus.com/inward/record.uri?eid=2-s2.0-105015510478&doi=10.1109%2fMetroAeroSpace64938.2025.11114637&partnerID=40&md5=7eb302fc7d501619ffc0077b7e307cfc | V16: scopus | Y16: yes | AA16: 2-s2.0-105015510478 | AB16: verified_scopus | AC16: https://www.scopus.com/inward/record.uri?eid=2-s2.0-105015510478&doi=10.1109%2fMetroAeroSpace64938.2025.11114637&partnerID=40&md5=7eb302fc7d501619ffc0077b7e307cfc
A17: scopus-10-33012-2025-19974 | B17: 2025 | D17: The synthetic meta-signal observations: a multipath resistance assessment | E17: Giovanni Cappello; Ciro Gioia; Antonio Angrisano; Salvatore Gaglione | F17: Salvatore Gaglione | G17: Conference Paper | H17: Proceedings of the International Technical Meeting of The Institute of Navigation, ITM | O17: 10.33012/2025.19974 | P17: 10.33012/2025.19974 | S17: https://www.scopus.com/inward/record.uri?eid=2-s2.0-105001668620&doi=10.33012%2f2025.19974&partnerID=40&md5=e3784e375792ec1833f2de6d00e0ea7b | V17: scopus | Y17: yes | AA17: 2-s2.0-105001668620 | AB17: verified_scopus | AC17: https://www.scopus.com/inward/record.uri?eid=2-s2.0-105001668620&doi=10.33012%2f2025.19974&partnerID=40&md5=e3784e375792ec1833f2de6d00e0ea7b
A18: scopus-10-3390-agriengineering7040120 | B18: 2025 | C18: 2025-04 | D18: Tomato Leaf Detection, Segmentation, and Extraction in Real-Time Environment for Accurate Disease Detection | E18: Shahab Ul Islam; Giampaolo Ferraioli; Vito Pascazio | F18: Giampaolo Ferraioli | G18: Journal Article | H18: AgriEngineering | L18: 7 | M18: 4 | N18: 120 | O18: 10.3390/agriengineering7040120 | P18: 10.3390/agriengineering7040120 | S18: https://doi.org/10.3390/agriengineering7040120 | V18: scopus | Y18: yes | AB18: verified_scopus | AC18: https://ouci.dntb.gov.ua/en/works/l111xP2y/
A19: scopus-10-3390-engproc2025088014 | B19: 2025 | D19: Toward Context-Aware GNSS Positioning: A Preliminary Analysis | E19: Giovanni Cappello; Antonio Maratea; Ciro Gioia; Antonio Angrisano; Silvio Del Pizzo; Salvatore Gaglione | F19: Silvio Del Pizzo; Salvatore Gaglione | G19: Journal Article | H19: Engineering Proceedings | L19: 88 | O19: 10.3390/engproc2025088014 | P19: 10.3390/engproc2025088014 | S19: https://www.scopus.com/inward/record.uri?eid=2-s2.0-105023666393&doi=10.3390%2fengproc2025088014&partnerID=40&md5=062a75da7c74085f6b1f50a1bc441882 | V19: scopus | Y19: yes | AA19: 2-s2.0-105023666393 | AB19: verified_scopus | AC19: https://www.scopus.com/inward/record.uri?eid=2-s2.0-105023666393&doi=10.3390%2fengproc2025088014&partnerID=40&md5=062a75da7c74085f6b1f50a1bc441882
A20: drupal-258 | B20: 2024 | D20: An Action-Camera Based Stereo System for MicroROV for Monitoring Coralline Algae in the Mediterranean Sea: Preliminary Assessment | E20: Silvio Del Pizzo; Erica Nocerino; Salvatore Gaglione; Alessio Calantropio; Fabio Menna; Salvatore Troisi | F20: Silvio Del Pizzo; Salvatore Gaglione; Salvatore Troisi | G20: Conference Paper | H20: 2024 IEEE International Workshop on Metrology for the Sea, MetroSea 2024 - Proceedings | O20: 10.1109/MetroSea62823.2024.10765774 | P20: 10.1109/MetroSea62823.2024.10765774 | S20: https://www.scopus.com/inward/record.uri?eid=2-s2.0-85214391242&doi=10.1109%2fMetroSea62823.2024.10765774&partnerID=40&md5=2d0c92ac8be583233e06effe4d12532f | U20: eng | V20: drupal | W20: 258 | X20: 1 | Y20: yes | AB20: legacy_drupal_historical
A21: drupal-256 | B21: 2024 | D21: Analysis of HAS performance in pedestrian navigation with different grade devices | E21: Antonio Angrisano; Milad Bagheri; Giovanni Cappello; Paolo Dabove; Silvio Del Pizzo; Salvatore Gaglione; Ciro Gioia; Gabriele Portelli; Salvatore Troisi | F21: Silvio Del Pizzo; Salvatore Gaglione; Salvatore Troisi | G21: Journal Article | H21: Proceedings of the International Technical Meeting of the Satellite Division of The Institute of Navigation, ION GNSS+ | N21: 2123 – 2135 | O21: 10.33012/2024.19785 | P21: 10.33012/2024.19785 | S21: https://www.scopus.com/inward/record.uri?eid=2-s2.0-105012766205&doi=10.33012%2f2024.19785&partnerID=40&md5=e81c13a01c9e0d13144add1c588eb12c | U21: eng | V21: drupal | W21: 256 | X21: 1 | Y21: yes | AB21: legacy_drupal_historical
A22: drupal-261 | B22: 2024 | D22: Correlation of Collision Damage Statistical Properties by Gaussian Copula Functions | E22: Salvatore Gaglione; Vincenzo Piscopo; Andrea Sciacca | F22: Salvatore Gaglione; Vincenzo Piscopo | G22: Conference Paper | H22: 2024 IEEE International Workshop on Metrology for the Sea, MetroSea 2024 - Proceedings | O22: 10.1109/MetroSea62823.2024.10765782 | P22: 10.1109/MetroSea62823.2024.10765782 | S22: https://www.scopus.com/inward/record.uri?eid=2-s2.0-85214363453&doi=10.1109%2fMetroSea62823.2024.10765782&partnerID=40&md5=14f1ce4e0d1531fda790a79b0eae0ad1 | U22: eng | V22: drupal | W22: 261 | X22: 1 | Y22: yes | AB22: legacy_drupal_historical
A23: drupal-259 | B23: 2024 | D23: GNSS-Based Velocity Measurement for Smart Mobility Systems | E23: Antonio Angrisano; Luigi Ferrigno; Salvatore Gaglione; Gianfranco Miele; Keerthana Velusamy | F23: Salvatore Gaglione | G23: Conference Paper | H23: 2024 IEEE International Symposium on Measurements and Networking, M and N 2024 - Proceedings | O23: 10.1109/MN60932.2024.10615589 | P23: 10.1109/MN60932.2024.10615589 | S23: https://www.scopus.com/inward/record.uri?eid=2-s2.0-85201282172&doi=10.1109%2fMN60932.2024.10615589&partnerID=40&md5=5ea07535af170ea0a0c98f82003e0e57 | U23: eng | V23: drupal | W23: 259 | X23: 1 | Y23: yes | AB23: legacy_drupal_historical
A24: drupal-257 | B24: 2024 | D24: Test of Galileo HAS in Precise Maritime Survey | E24: Antonio Angrisano; Giovanni Cappello; Silvio Del Pizzo; Salvatore Gaglione; Ciro Gioia; Gabriele Portelli; Salvatore Troisi | F24: Silvio Del Pizzo; Salvatore Gaglione; Salvatore Troisi | G24: Conference Paper | H24: 2024 IEEE International Workshop on Metrology for the Sea, MetroSea 2024 - Proceedings | O24: 10.1109/MetroSea62823.2024.10765743 | P24: 10.1109/MetroSea62823.2024.10765743 | S24: https://www.scopus.com/inward/record.uri?eid=2-s2.0-85214362769&doi=10.1109%2fMetroSea62823.2024.10765743&partnerID=40&md5=713959dc325e54a403184d6b7aadc894 | U24: eng | V24: drupal | W24: 257 | X24: 1 | Y24: yes | AB24: legacy_drupal_historical
A25: drupal-262 | B25: 2024 | D25: The 3d reconstruction of the sansevero chapel anatomical machines: A geomatics challenge | E25: Silvio Del Pizzo; Fabiana Di Ciaccio; Salvatore Gaglione; F.M. Galassi; V. Papa; E. Varotto; Salvatore Troisi | F25: Silvio Del Pizzo; Salvatore Gaglione; Salvatore Troisi | G25: Conference Paper | H25: International Archives of the Photogrammetry, Remote Sensing and Spatial Information Sciences - ISPRS Archives | O25: 10.5194/isprs-Archives-XLVIII-2-W4-2024-173-2024 | P25: 10.5194/isprs-Archives-XLVIII-2-W4-2024-173-2024 | S25: https://www.scopus.com/inward/record.uri?eid=2-s2.0-85186960308&doi=10.5194%2fisprs-Archives-XLVIII-2-W4-2024-173-2024&partnerID=40&md5=d5d299a56153d9ea77e6f6cd098e499e | U25: eng | V25: drupal | W25: 262 | X25: 1 | Y25: yes | AB25: legacy_drupal_historical
A26: drupal-260 | B26: 2024 | D26: Velocity Estimation Using Time-Differenced Carrier Phase and Doppler Shift with Different Grades of Devices: From Smartphones to Professional Receivers | E26: Antonio Angrisano; Giovanni Cappello; Salvatore Gaglione; Ciro Gioia | F26: Salvatore Gaglione | G26: Journal Article | H26: Algorithms | L26: 17 | O26: 10.3390/a17010002 | P26: 10.3390/a17010002 | S26: https://www.scopus.com/inward/record.uri?eid=2-s2.0-85183172433&doi=10.3390%2fa17010002&partnerID=40&md5=8afa55dd42780951d37d263b0eeaade4 | U26: eng | V26: drupal | W26: 260 | X26: 1 | Y26: yes | AB26: legacy_drupal_historical
A27: drupal-247 | B27: 2023 | D27: An Enhanced Photogrammetric Approach for the Underwater Surveying of the Posidonia Meadow Structure in the Spiaggia Nera Area of Maratea | E27: Francesca Russo; Silvio Del Pizzo; Fabiana Di Ciaccio; Salvatore Troisi | F27: Silvio Del Pizzo; Salvatore Troisi | G27: Journal Article | H27: Journal of Imaging | L27: 9 | N27: 113 | U27: eng | V27: drupal | W27: 247 | X27: 1 | Y27: yes | Z27: missing_doi | AB27: legacy_drupal_historical
A28: drupal-243 | B28: 2023 | D28: Application of “Galileo High Accuracy Service” on Single-Point Positioning | E28: Antonio Angrisano; Silvia Ascione; Giovanni Cappello; Ciro Gioia; Salvatore Gaglione | F28: Salvatore Gaglione | G28: Journal Article | H28: Sensors | L28: 23 | O28: 10.3390/s23094223 | P28: 10.3390/s23094223 | S28: https://www.scopus.com/inward/record.uri?eid=2-s2.0-85159187764&doi=10.3390%2fs23094223&partnerID=40&md5=ae572f6afd7651a924051f8c60baeda9 | U28: eng | V28: drupal | W28: 243 | X28: 1 | Y28: yes | AB28: legacy_drupal_historical
A29: drupal-254 | B29: 2023 | D29: Application of “Galileo High Accuracy Service” on Single-Point Positioning | E29: Antonio Angrisano; Silvia Ascione; Giovanni Cappello; Ciro Gioia; Salvatore Gaglione | F29: Salvatore Gaglione | G29: Journal Article | H29: Sensors | L29: 23 | O29: 10.3390/s23094223 | P29: 10.3390/s23094223 | S29: https://www.scopus.com/inward/record.uri?eid=2-s2.0-85159187764&doi=10.3390%2fs23094223&partnerID=40&md5=ae572f6afd7651a924051f8c60baeda9 | U29: eng | V29: drupal | W29: 254 | X29: 1 | Y29: yes | AB29: legacy_drupal_historical
A30: drupal-244 | B30: 2023 | D30: Demonstrating Galileo Has in Single Point Positioning | E30: Giovanni Cappello; Antonio Angrisano; Silvia Ascione; Silvio Del Pizzo; Ciro Gioia; Gabriele Portelli; Melania Susi; Salvatore Gaglione | F30: Silvio Del Pizzo; Salvatore Gaglione | G30: Conference Paper | H30: 2023 IEEE International Workshop on Metrology for Automotive (MetroAutomotive) | O30: 10.1109/MetroAutomotive57488.2023.10219138 | P30: 10.1109/MetroAutomotive57488.2023.10219138 | U30: eng | V30: drupal | W30: 244 | X30: 1 | Y30: yes | AB30: legacy_drupal_historical
A31: drupal-250 | B31: 2023 | D31: Enhancing navigation solution with Galileo HAS | E31: Gabriele Portelli; Antonio Angrisano; Giovanni Cappello; Silvio Del Pizzo; Ciro Gioia; Salvatore Troisi; Salvatore Gaglione | F31: Silvio Del Pizzo; Salvatore Troisi; Salvatore Gaglione | G31: Conference Paper | H31: 2023 IEEE International Workshop on Metrology for the Sea; Learning to Measure Sea Health Parameters, MetroSea 2023 - Proceedings | O31: 10.1109/MetroSea58055.2023.10317475 | P31: 10.1109/MetroSea58055.2023.10317475 | S31: https://www.scopus.com/inward/record.uri?eid=2-s2.0-85179760632&doi=10.1109%2fMetroSea58055.2023.10317475&partnerID=40&md5=4bdaad2f44110baa3a7f574c5fcca34e | U31: eng | V31: drupal | W31: 250 | X31: 1 | Y31: yes | AB31: legacy_drupal_historical
A32: drupal-245 | B32: 2023 | D32: Galileo-Based Doppler Shifts and Time Difference Carrier Phase: A Static Case Demonstration | E32: Ciro Gioia; Antonio Angrisano; Salvatore Gaglione | F32: Salvatore Gaglione | G32: Journal Article | H32: Sensors | L32: 23 | N32: 6828 | U32: eng | V32: drupal | W32: 245 | X32: 1 | Y32: yes | Z32: missing_doi | AB32: legacy_drupal_historical
A33: drupal-255 | B33: 2023 | D33: Galileo-Based Doppler Shifts and Time Difference Carrier Phase: A Static Case Demonstration | E33: Ciro Gioia; Antonio Angrisano; Salvatore Gaglione | F33: Salvatore Gaglione | G33: Journal Article | H33: Sensors | L33: 23 | O33: 10.3390/s23156828 | P33: 10.3390/s23156828 | S33: https://www.scopus.com/inward/record.uri?eid=2-s2.0-85167770866&doi=10.3390%2fs23156828&partnerID=40&md5=d69193446808e4fbeb3782abda0ab86b | U33: eng | V33: drupal | W33: 255 | X33: 1 | Y33: yes | AB33: legacy_drupal_historical
A34: drupal-234 | B34: 2023 | D34: Hydrodynamic Design of Fixed Hydrofoils for Planing Craft | E34: Egidio D’Amato; Immacolata Notaro; Vincenzo Piscopo; Antonio Scamardella | F34: Vincenzo Piscopo; Antonio Scamardella | G34: Journal Article | H34: Journal of Marine Science and Engineering | L34: 11 | O34: 10.3390/jmse11020246 | P34: 10.3390/jmse11020246 | S34: https://www.scopus.com/inward/record.uri?eid=2-s2.0-85149140611&doi=10.3390%2fjmse11020246&partnerID=40&md5=2cd47d37808972072d2e4a35a528c2ab | U34: eng | V34: drupal | W34: 234 | X34: 1 | Y34: yes | AB34: legacy_drupal_historical
A35: drupal-252 | B35: 2023 | D35: Incidence of parametrized methods for spectral analysis of Ship Motion | E35: Silvia Ascione; Salvatore Gaglione; Vincenzo Piscopo; Antonio Scamardella | F35: Salvatore Gaglione; Vincenzo Piscopo; Antonio Scamardella | G35: Conference Paper | H35: 2023 IEEE International Workshop on Metrology for the Sea; Learning to Measure Sea Health Parameters, MetroSea 2023 - Proceedings | O35: 10.1109/MetroSea58055.2023.10317389 | P35: 10.1109/MetroSea58055.2023.10317389 | S35: https://www.scopus.com/inward/record.uri?eid=2-s2.0-85179753312&doi=10.1109%2fMetroSea58055.2023.10317389&partnerID=40&md5=18038ff73c03b5a7fba74943e87e7bb8 | U35: eng | V35: drupal | W35: 252 | X35: 1 | Y35: yes | AB35: legacy_drupal_historical
A36: drupal-238 | B36: 2023 | D36: Motions Assessment Using a Time Domain Approach for a Research Ship in Antarctic Waters | E36: Silvia Pennino; Antonio Scamardella | F36: Silvia Pennino; Antonio Scamardella | G36: Journal Article | H36: Journal of Marine Science and Engineering | L36: 11 | O36: 10.3390/jmse11030558 | P36: 10.3390/jmse11030558 | S36: https://www.scopus.com/inward/record.uri?eid=2-s2.0-85151472339&doi=10.3390%2fjmse11030558&partnerID=40&md5=c0a42499d792671ff743c0f68da53828 | U36: eng | V36: drupal | W36: 238 | X36: 1 | Y36: yes | AB36: legacy_drupal_historical
A37: drupal-239 | B37: 2023 | D37: Neustrelitz Total Electron Content Model for Galileo Performance: A Position Domain Analysis | E37: Ciro Gioia; Antonio Angrisano; Salvatore Gaglione | F37: Salvatore Gaglione | G37: Journal Article | H37: Sensors (Basel, Switzerland) | L37: 23 | O37: 10.3390/s23073766 | P37: 10.3390/s23073766 | S37: https://www.scopus.com/inward/record.uri?eid=2-s2.0-85152305860&doi=10.3390%2fs23073766&partnerID=40&md5=fb7b82a05b8f07743fd2687f5cf0732c | U37: eng | V37: drupal | W37: 239 | X37: 1 | Y37: yes | AB37: legacy_drupal_historical
A38: drupal-253 | B38: 2023 | D38: Neustrelitz Total Electron Content Model for Galileo Performance: A Position Domain Analysis | E38: Ciro Gioia; Antonio Angrisano; Salvatore Gaglione | F38: Salvatore Gaglione | G38: Journal Article | H38: Sensors | L38: 23 | O38: 10.3390/s23073766 | P38: 10.3390/s23073766 | S38: https://www.scopus.com/inward/record.uri?eid=2-s2.0-85152305860&doi=10.3390%2fs23073766&partnerID=40&md5=fb7b82a05b8f07743fd2687f5cf0732c | U38: eng | V38: drupal | W38: 253 | X38: 1 | Y38: yes | AB38: legacy_drupal_historical
A39: drupal-246 | B39: 2023 | D39: Reconstructing anthropic coastal landscape of Campi Flegrei volcanic area (Southern Italy) during the Roman period from multi-technique surveys | E39: Gaia Mattei; Lucio Amato; Claudia Caporizzo; Aldo Cinque; Gerardo Pappone; Alessia Sorrentino; Paolo Stocchi; Salvatore Troisi; Pietro PC Aucelli | F39: Salvatore Troisi | G39: Journal Article | H39: Journal of Maps | N39: 1–14 | U39: eng | V39: drupal | W39: 246 | X39: 1 | Y39: yes | Z39: ambiguous_author:Aucelli, Pietro PC; missing_doi | AB39: legacy_drupal_historical
A40: drupal-251 | B40: 2023 | D40: Reliability of Smartphone Positioning in Harsh Environment † | E40: Giovanni Cappello; Ciro Gioia; Antonio Angrisano; Silvio Del Pizzo; Gabriele Portelli; Salvatore Gaglione | F40: Silvio Del Pizzo; Salvatore Gaglione | G40: Journal Article | H40: Engineering Proceedings | L40: 54 | O40: 10.3390/ENC2023-15429 | P40: 10.3390/ENC2023-15429 | S40: https://www.scopus.com/inward/record.uri?eid=2-s2.0-85186439748&doi=10.3390%2fENC2023-15429&partnerID=40&md5=2140d47215ca7c12bf2c156d766cae6c | U40: eng | V40: drupal | W40: 251 | X40: 1 | Y40: yes | AB40: legacy_drupal_historical
...

Sheet Scopus review
A1: publication_id | B1: year | C1: date | D1: title | E1: authors | F1: pang_faculty_authors | G1: document_type | H1: source_title | I1: volume | J1: issue | K1: pages | L1: doi | M1: scopus_eid | N1: scopus_url | O1: source_url | P1: verification_status | Q1: verification_evidence | R1: include_in_master | S1: notes
A2: scopus-10-1109-taes-2025-3619912 | B2: 2026 | D2: A Split Pulse Fusion Method for Radar Reconnaissance | E2: Ronghua Guo; Yang-Yang Dong; Dan Bao; Chunxi Dong; Sergio Vitale; Giampaolo Ferraioli; Vito Pascazio; Wenbo Li; Zhiyuan Li | F2: Giampaolo Ferraioli | G2: Journal Article | H2: IEEE Transactions on Aerospace and Electronic Systems | I2: 62 | K2: 217-233 | L2: 10.1109/TAES.2025.3619912 | O2: https://www.sciencedirect.com/author/7003486376/vito-pascazio | P2: verified_scopus | Q2: ScienceDirect author page labels the publication “Scopus Article”. | R2: yes
A3: scopus-10-3390-geomatics6010004 | B3: 2026 | C3: 2026-01-10 | D3: Evaluating Neural Radiance Fields for Image-Based 3D Reconstruction: A Comparative Study with SfM-MVS | E3: Alessia Giaquinto; Giampaolo Ferraioli; Silvio Del Pizzo | F3: Giampaolo Ferraioli; Silvio Del Pizzo | G3: Journal Article | H3: Geomatics | I3: 6 | J3: 1 | K3: 4 | L3: 10.3390/geomatics6010004 | O3: https://www.mdpi.com/2673-7418/6/1/4 | P3: pending_scopus | Q3: Publisher record confirmed; direct Scopus record/EID not yet retrieved. | R3: no
A4: scopus-10-3390-automation7020036 | B4: 2026 | C4: 2026-02-25 | D4: Intelligent Tomato Leaf Disease Detection and Automated Spray Prescription Using YOLOv9: A Smart Agriculture Approach | E4: Shahab Ul Islam; Giampaolo Ferraioli; Ghassan Husnain; Abdul Waheed; Vito Pascazio | F4: Giampaolo Ferraioli | G4: Journal Article | H4: Automation | I4: 7 | J4: 2 | K4: 36 | L4: 10.3390/automation7020036 | O4: https://www.sciencedirect.com/author/7003486376/vito-pascazio | P4: verified_scopus | Q4: ScienceDirect author page lists the Automation 2026 record as “Scopus Article”. | R4: yes
A5: scopus-10-3390-engproc2026126010 | B5: 2026 | C5: 2026-02-11 | D5: On the Context-Aware GNSS Navigation: Test of a k-Nearest Neighbors Classifier in Different Environments | E5: Giovanni Cappello; Antonio Angrisano; Ciro Gioia; Antonio Maratea; Salvatore Gaglione | F5: Salvatore Gaglione | G5: Conference Paper | H5: Engineering Proceedings | I5: 126 | J5: 1 | K5: 10 | L5: 10.3390/engproc2026126010 | O5: https://www.mdpi.com/2673-4591/126/1/10 | P5: pending_scopus | Q5: Publisher record confirmed; direct Scopus record/EID not yet retrieved. | R5: no
A6: scopus-10-1016-j-oceaneng-2025-123471 | B6: 2026 | C6: 2026-01-15 | D6: Sea state reconstruction based on the Spearman rank correlation using full-scale data from a containership | E6: Silvia Ascione; Ulrik D. Nielsen; Vincenzo Piscopo; Gaute Storhaug | F6: Vincenzo Piscopo | G6: Journal Article | H6: Ocean Engineering | I6: 343 | J6: Part 4 | K6: 123471 | L6: 10.1016/j.oceaneng.2025.123471 | O6: https://www.sciencedirect.com/author/57224792997/ulrik-dam-nielsen | P6: verified_scopus | Q6: ScienceDirect author page provides “View details in Scopus” for this article. | R6: yes
A7: scopus-10-1109-lgrs-2026-3659009 | B7: 2026 | D7: Sentinel-1 Ground Truth Dataset for Coastline Extraction | E7: Gianpaolo Passarello; Sergio Vitale; Giampaolo Ferraioli; Vito Pascazio | F7: Giampaolo Ferraioli | G7: Journal Article | H7: IEEE Geoscience and Remote Sensing Letters | I7: 23 | L7: 10.1109/LGRS.2026.3659009 | O7: https://www.sciencedirect.com/author/7003486376/vito-pascazio | P7: verified_scopus | Q7: ScienceDirect author page labels the publication “Scopus Article”. | R7: yes
A8: scopus-10-1109-lgrs-2025-3555441 | B8: 2025 | D8: A Deep Learning Solution for Phase Screen Estimation in SAR Tomography | E8: Hossein Aghababaei; Giampaolo Ferraioli; Sergio Vitale; Alfred Stein | F8: Giampaolo Ferraioli | G8: Journal Article | H8: IEEE Geoscience and Remote Sensing Letters | I8: 22 | K8: 4007605 | L8: 10.1109/LGRS.2025.3555441 | O8: https://research.utwente.nl/en/publications/a-deep-learning-solution-for-phase-screen-estimation-in-sar-tomog/ | P8: verified_scopus_indirect | Q8: University of Twente research portal exposes Scopus citation data for the publication. | R8: yes
A9: scopus-10-1109-metroaerospace64938-2025-11114485 | B9: 2025 | D9: A Micro Radar-Based Low-Cost Solution for Positioning and Detection, and Avoidance System | E9: Gennaro Ariante; Lucie Rocquelain; Salvatore Gaglione; Silvio Del Pizzo; Giuseppe Del Core | F9: Salvatore Gaglione; Silvio Del Pizzo | G9: Conference Paper | H9: 2025 IEEE International Workshop on Metrology for AeroSpace, MetroAeroSpace 2025 - Proceedings | L9: 10.1109/MetroAeroSpace64938.2025.11114485 | M9: 2-s2.0-105015377060 | N9: https://www.scopus.com/inward/record.uri?eid=2-s2.0-105015377060&doi=10.1109%2fMetroAeroSpace64938.2025.11114485&partnerID=40&md5=03287e527efef9f4adf9d23e9c84507f | O9: https://www.scopus.com/inward/record.uri?eid=2-s2.0-105015377060&doi=10.1109%2fMetroAeroSpace64938.2025.11114485&partnerID=40&md5=03287e527efef9f4adf9d23e9c84507f | P9: verified_scopus | Q9: Direct Scopus inward URL/EID stored in the legacy Drupal record. | R9: yes | S9: Recovered from Drupal 2025; treated as Scopus source for the new master.
A10: scopus-10-1016-j-oceaneng-2025-121579 | B10: 2025 | D10: A numerical model of ship manoeuvring for the KVLCC2 hull, in regular and long-crested irregular waves | E10: Maria Acanfora; Marco Altosole; Silvia Pennino | F10: Silvia Pennino | G10: Journal Article | H10: Ocean Engineering | I10: 333 | K10: 121579 | L10: 10.1016/j.oceaneng.2025.121579 | O10: https://ouci.dntb.gov.ua/works/9Gmm8Yyx/ | P10: verified_scopus | Q10: OUCI record explicitly marks the article as indexed in Scopus. | R10: yes
A11: scopus-10-1109-metrosea66681-2025-11245754 | B11: 2025 | D11: Advancing Offshore Renewable Energy in the Mediterranean Sea: Digital-Med, a Project for Integrating Resource Assessment and Decision Support | E11: Silvio Del Pizzo; Salvatore Gaglione; Pier Paolo Amoroso; Pasquale Contestabile; Yuri Cotroneo; Francesco Giuseppe Figliomeni; Diego Vicinanza; Giorgio Budillon | F11: Silvio Del Pizzo; Salvatore Gaglione | G11: Conference Paper | H11: 2025 IEEE International Workshop on Metrology for the Sea; Learning to Measure Sea Health Parameters, MetroSea 2025 - Proceedings | L11: 10.1109/MetroSea66681.2025.11245754 | M11: 2-s2.0-105029542122 | N11: https://www.scopus.com/inward/record.uri?eid=2-s2.0-105029542122&doi=10.1109%2fMetroSea66681.2025.11245754&partnerID=40&md5=deea9b4f945a9ec20267bce45c30d977 | O11: https://www.scopus.com/inward/record.uri?eid=2-s2.0-105029542122&doi=10.1109%2fMetroSea66681.2025.11245754&partnerID=40&md5=deea9b4f945a9ec20267bce45c30d977 | P11: verified_scopus | Q11: Direct Scopus inward URL/EID stored in the legacy Drupal record. | R11: yes | S11: Recovered from Drupal 2025; treated as Scopus source for the new master.
A12: scopus-10-1109-igarss55030-2025-11243038 | B12: 2025 | C12: 2025-08 | D12: An Open-Access Cross-Modal Forest Benchmark Training Dataset With Sentinel-1 and Lidar data | E12: Hossein Aghababaei; Giampaolo Ferraioli; Gilda Schirinzi; Erkki Tomppo; Jaan Praks | F12: Giampaolo Ferraioli | G12: Conference Paper | H12: IGARSS 2025 - 2025 IEEE International Geoscience and Remote Sensing Symposium | K12: 3588-3591 | L12: 10.1109/IGARSS55030.2025.11243038 | M12: 2-s2.0-105034117757 | N12: https://www.scopus.com/pages/publications/105034117757 | O12: https://research.aalto.fi/en/publications/an-open-access-cross-modal-forest-benchmark-training-dataset-with/ | P12: verified_scopus | Q12: Aalto research portal exposes direct Scopus URL and AN=SCOPUS:105034117757. | R12: yes
A13: scopus-10-1016-j-oceaneng-2025-122258 | B13: 2025 | C13: 2025-11-30 | D13: Assessment of bimodal sea states by the wave buoy analogy method | E13: Vincenzo Piscopo; Silvia Ascione; Antonio Scamardella | F13: Vincenzo Piscopo; Antonio Scamardella | G13: Journal Article | H13: Ocean Engineering | I13: 340 | J13: Part 1 | K13: 122258 | L13: 10.1016/j.oceaneng.2025.122258 | O13: https://www.sciencedirect.com/author/6507257720/v-piscopo | P13: verified_scopus | Q13: ScienceDirect author page provides “View details in Scopus”; OUCI independently labels the record Scopus. | R13: yes
A14: scopus-10-1038-s41598-025-00653-8 | B14: 2025 | C14: 2025-05-12 | D14: Augustus’ solar meridian functioning and the birth of the western leap year | E14: V. Baiocchi; M. Baumgartner; M. Barbarella; M. T. D’Alessio; Silvio Del Pizzo; F. Giannone; F. Radicioni; A. Stoppini; G. Tosi; Salvatore Troisi; L. Alessandri | F14: Silvio Del Pizzo; Salvatore Troisi | G14: Journal Article | H14: Scientific Reports | I14: 15 | K14: 16463 | L14: 10.1038/s41598-025-00653-8 | O14: https://research.rug.nl/en/publications/augustus-solar-meridian-functioning-and-the-birth-of-the-western-/ | P14: verified_scopus_indirect | Q14: University of Groningen research portal reports Scopus citation data for this record. | R14: yes
A15: scopus-10-3233-pmst250035 | B15: 2025 | C15: 2025-08-12 | D15: Development and Application of a Numerical Model for Ship Manoeuvring in Regular and Irregular Waves | E15: Maria Acanfora; Silvia Pennino; Antonio Scamardella | F15: Silvia Pennino; Antonio Scamardella | G15: Conference Paper / Book Chapter | H15: Technology and Science for the Ships of the Future | L15: 10.3233/PMST250035 | O15: https://journals.sagepub.com/doi/10.3233/PMST250035 | P15: pending_scopus | Q15: Publisher record confirmed; direct Scopus record/EID not yet retrieved. | R15: no
A16: scopus-10-1109-lgrs-2025-3577907 | B16: 2025 | D16: Enhanced Deep Learning SAR Despeckling Networks Based on SAR Assessing Metrics | E16: Sergio Vitale; Giampaolo Ferraioli; Vito Pascazio; Luis Gomez Deniz | F16: Giampaolo Ferraioli | G16: Journal Article | H16: IEEE Geoscience and Remote Sensing Letters | I16: 22 | K16: 4009305 | L16: 10.1109/LGRS.2025.3577907 | O16: https://accedacris.ulpgc.es/handle/10553/141828 | P16: probable_scopus | Q16: Published in IEEE GRSL; public CRIS confirms metadata, but no direct Scopus EID was exposed in the retrieved record. | R16: no | S16: Keep pending until direct Scopus confirmation/EID is obtained.
A17: scopus-10-1109-lgrs-2025-3580932 | B17: 2025 | C17: 2025-07-17 | D17: Erratum to “A deep learning solution for phase screen estimation in SAR tomography” | E17: Hossein Aghababaei; Giampaolo Ferraioli; Sergio Vitale; Alfred Stein | F17: Giampaolo Ferraioli | G17: Erratum | H17: IEEE Geoscience and Remote Sensing Letters | I17: 22 | K17: 1-1 | L17: 10.1109/LGRS.2025.3580932 | O17: https://research.utwente.nl/en/publications/erratum-to-a-deep-learning-solution-for-phase-screen-estimation-i/ | P17: probable_scopus | Q17: Twente record links the parent publication to Scopus; direct Scopus identifier for the erratum was not exposed. | R17: no | S17: Pending direct Scopus confirmation.
A18: scopus-10-1109-mgrs-2025-3612752 | B18: 2025 | C18: 2025-12-17 | D18: IEEE Geoscience and Remote Sensing Society Awards Presented at the IEEE International Geoscience and Remote Sensing Symposium 2025 Awards Reception and Ceremony | E18: Francesca Bovolo; Jaya Sreevalsan-Nair; Antonio Plaza; Alberto Moreira; Giampaolo Ferraioli; Claudio Persello | F18: Giampaolo Ferraioli | G18: Conference Report | H18: IEEE Geoscience and Remote Sensing Magazine | I18: 13 | K18: 444-454 | L18: 10.1109/MGRS.2025.3612752 | O18: https://elib.dlr.de/222017/ | P18: verified_scopus | Q18: DLR publication record explicitly states “In SCOPUS: Ja”. | R18: yes | S18: Non-research conference report; retain with document_type so it can be filtered if desired.
A19: scopus-10-1109-mgrs-2025-3599367 | B19: 2025 | C19: 2025-12 | D19: IGARSS 2025 in Brisbane, Australia: Impressions of the First Days | E19: Alberto Moreira; Francesca Bovolo; Jaya Sreevalsan-Nair; Giampaolo Ferraioli | F19: Giampaolo Ferraioli | G19: Conference Report | H19: IEEE Geoscience and Remote Sensing Magazine | I19: 13 | J19: 4 | K19: 430-443 | L19: 10.1109/MGRS.2025.3599367 | O19: https://elib.dlr.de/218787/ | P19: verified_scopus | Q19: DLR publication record explicitly states “In SCOPUS: Ja”. | R19: yes | S19: Non-research conference report; retain with document_type so it can be filtered if desired.
A20: scopus-10-3233-pmst250112 | B20: 2025 | C20: 2025-08-12 | D20: Incidence of Rank Correlation Algorithm on the Assessment of Bimodal Sea State Conditions Based on Ship Motion Analysis | E20: Vincenzo Piscopo; Antonio Scamardella | F20: Vincenzo Piscopo; Antonio Scamardella | G20: Conference Paper / Book Chapter | H20: Technology and Science for the Ships of the Future | L20: 10.3233/PMST250112 | O20: https://journals.sagepub.com/doi/10.3233/PMST250112 | P20: pending_scopus | Q20: Publisher record confirmed; direct Scopus record/EID not yet retrieved. | R20: no
A21: scopus-10-33012-2025-19984 | B21: 2025 | D21: The G4 Solar Storm of May 2024: Impact on the GNSS carrier-phase measurements | E21: Giovanni Cappello; Ciro Gioia; Antonio Angrisano; Gabriele Portelli; Salvatore Gaglione | F21: Salvatore Gaglione | G21: Conference Paper | H21: Proceedings of the International Technical Meeting of The Institute of Navigation, ITM | L21: 10.33012/2025.19984 | M21: 2-s2.0-105001675036 | N21: https://www.scopus.com/inward/record.uri?eid=2-s2.0-105001675036&doi=10.33012%2f2025.19984&partnerID=40&md5=739f848160bb42247f9941f85f76ae90 | O21: https://www.scopus.com/inward/record.uri?eid=2-s2.0-105001675036&doi=10.33012%2f2025.19984&partnerID=40&md5=739f848160bb42247f9941f85f76ae90 | P21: verified_scopus | Q21: Direct Scopus inward URL/EID stored in the legacy Drupal record. | R21: yes | S21: Recovered from Drupal 2025; treated as Scopus source for the new master.
A22: scopus-10-1109-metroaerospace64938-2025-11114637 | B22: 2025 | D22: The Galileo-based UAV velocity: Doppler and Time-Differenced Carrier Phase | E22: Giovanni Cappello; Ciro Gioia; Andrea Piccolo; Antonio Angrisano; Salvatore Gaglione | F22: Salvatore Gaglione | G22: Conference Paper | H22: 2025 IEEE International Workshop on Metrology for AeroSpace, MetroAeroSpace 2025 - Proceedings | L22: 10.1109/MetroAeroSpace64938.2025.11114637 | M22: 2-s2.0-105015510478 | N22: https://www.scopus.com/inward/record.uri?eid=2-s2.0-105015510478&doi=10.1109%2fMetroAeroSpace64938.2025.11114637&partnerID=40&md5=7eb302fc7d501619ffc0077b7e307cfc | O22: https://www.scopus.com/inward/record.uri?eid=2-s2.0-105015510478&doi=10.1109%2fMetroAeroSpace64938.2025.11114637&partnerID=40&md5=7eb302fc7d501619ffc0077b7e307cfc | P22: verified_scopus | Q22: Direct Scopus inward URL/EID stored in the legacy Drupal record. | R22: yes | S22: Recovered from Drupal 2025; treated as Scopus source for the new master.
A23: scopus-10-33012-2025-19974 | B23: 2025 | D23: The synthetic meta-signal observations: a multipath resistance assessment | E23: Giovanni Cappello; Ciro Gioia; Antonio Angrisano; Salvatore Gaglione | F23: Salvatore Gaglione | G23: Conference Paper | H23: Proceedings of the International Technical Meeting of The Institute of Navigation, ITM | L23: 10.33012/2025.19974 | M23: 2-s2.0-105001668620 | N23: https://www.scopus.com/inward/record.uri?eid=2-s2.0-105001668620&doi=10.33012%2f2025.19974&partnerID=40&md5=e3784e375792ec1833f2de6d00e0ea7b | O23: https://www.scopus.com/inward/record.uri?eid=2-s2.0-105001668620&doi=10.33012%2f2025.19974&partnerID=40&md5=e3784e375792ec1833f2de6d00e0ea7b | P23: verified_scopus | Q23: Direct Scopus inward URL/EID stored in the legacy Drupal record. | R23: yes | S23: Recovered from Drupal 2025; treated as Scopus source for the new master.
A24: scopus-10-3390-agriengineering7040120 | B24: 2025 | C24: 2025-04 | D24: Tomato Leaf Detection, Segmentation, and Extraction in Real-Time Environment for Accurate Disease Detection | E24: Shahab Ul Islam; Giampaolo Ferraioli; Vito Pascazio | F24: Giampaolo Ferraioli | G24: Journal Article | H24: AgriEngineering | I24: 7 | J24: 4 | K24: 120 | L24: 10.3390/agriengineering7040120 | O24: https://ouci.dntb.gov.ua/en/works/l111xP2y/ | P24: verified_scopus | Q24: OUCI record explicitly marks the article as indexed in Scopus. | R24: yes
A25: scopus-10-3390-engproc2025088014 | B25: 2025 | D25: Toward Context-Aware GNSS Positioning: A Preliminary Analysis | E25: Giovanni Cappello; Antonio Maratea; Ciro Gioia; Antonio Angrisano; Silvio Del Pizzo; Salvatore Gaglione | F25: Silvio Del Pizzo; Salvatore Gaglione | G25: Journal Article | H25: Engineering Proceedings | I25: 88 | L25: 10.3390/engproc2025088014 | M25: 2-s2.0-105023666393 | N25: https://www.scopus.com/inward/record.uri?eid=2-s2.0-105023666393&doi=10.3390%2fengproc2025088014&partnerID=40&md5=062a75da7c74085f6b1f50a1bc441882 | O25: https://www.scopus.com/inward/record.uri?eid=2-s2.0-105023666393&doi=10.3390%2fengproc2025088014&partnerID=40&md5=062a75da7c74085f6b1f50a1bc441882 | P25: verified_scopus | Q25: Direct Scopus inward URL/EID stored in the legacy Drupal record. | R25: yes | S25: Recovered from Drupal 2025; treated as Scopus source for the new master.
A26: scopus-10-5194-isprs-archives-xlviii-2-w10-2025-207-2025 | B26: 2025 | C26: 2025-07-07 | D26: Underwater optical metrology for precision monitoring of marine habitats: the MANATEE project | E26: Erica Nocerino; Fabio Menna; Alessio Calantropio; Federico Pinna; Silvio Del Pizzo; Simone Farina; Alessia Giaquinto; Alessandro Lambertini; Massimiliano Menghini; Shahriar Mokhtari; Federica Ragazzola; Salvatore Troisi; Luca Vittuari | F26: Silvio Del Pizzo; Salvatore Troisi | G26: Conference Paper | H26: The International Archives of the Photogrammetry, Remote Sensing and Spatial Information Sciences | I26: XLVIII-2/W10-2025 | K26: 207-214 | L26: 10.5194/isprs-archives-XLVIII-2-W10-2025-207-2025 | O26: https://isprs-archives.copernicus.org/articles/XLVIII-2-W10-2025/207/2025/index.html | P26: pending_scopus | Q26: Bibliographic record confirmed by publisher; direct Scopus record/EID not yet retrieved. | R26: no
A27: scopus-10-5194-isprs-archives-xlviii-2-w10-2025-47-2025 | B27: 2025 | C27: 2025-07-07 | D27: Underwater synthetic image generation for multi-temporal monitoring of crustose coralline algae | E27: Alessio Calantropio; Alessia Giaquinto; Silvio Del Pizzo; Fabio Menna; Erica Nocerino | F27: Silvio Del Pizzo | G27: Conference Paper | H27: The International Archives of the Photogrammetry, Remote Sensing and Spatial Information Sciences | I27: XLVIII-2/W10-2025 | K27: 47-54 | L27: 10.5194/isprs-archives-XLVIII-2-W10-2025-47-2025 | O27: https://isprs-archives.copernicus.org/articles/XLVIII-2-W10-2025/47/2025/isprs-archives-XLVIII-2-W10-2025-47-2025.html | P27: pending_scopus | Q27: Bibliographic record confirmed by publisher; direct Scopus record/EID not yet retrieved. | R27: no

Sheet Faculty coverage
A1: Faculty | B1: Verified/Included | C1: Pending/Probable | D1: Total candidates
A2: Salvatore Gaglione | B2: =COUNTIFS('Scopus review'!$F:$F,"*"&A2&"*",'Scopus review'!$R:$R,"yes") | C2: =COUNTIFS('Scopus review'!$F:$F,"*"&A2&"*",'Scopus review'!$R:$R,"no") | D2: =B2+C2
A3: Salvatore Troisi | B3: =COUNTIFS('Scopus review'!$F:$F,"*"&A3&"*",'Scopus review'!$R:$R,"yes") | C3: =COUNTIFS('Scopus review'!$F:$F,"*"&A3&"*",'Scopus review'!$R:$R,"no") | D3: =B3+C3
A4: Silvio Del Pizzo | B4: =COUNTIFS('Scopus review'!$F:$F,"*"&A4&"*",'Scopus review'!$R:$R,"yes") | C4: =COUNTIFS('Scopus review'!$F:$F,"*"&A4&"*",'Scopus review'!$R:$R,"no") | D4: =B4+C4
A5: Giampaolo Ferraioli | B5: =COUNTIFS('Scopus review'!$F:$F,"*"&A5&"*",'Scopus review'!$R:$R,"yes") | C5: =COUNTIFS('Scopus review'!$F:$F,"*"&A5&"*",'Scopus review'!$R:$R,"no") | D5: =B5+C5
A6: Vincenzo Piscopo | B6: =COUNTIFS('Scopus review'!$F:$F,"*"&A6&"*",'Scopus review'!$R:$R,"yes") | C6: =COUNTIFS('Scopus review'!$F:$F,"*"&A6&"*",'Scopus review'!$R:$R,"no") | D6: =B6+C6
A7: Antonio Scamardella | B7: =COUNTIFS('Scopus review'!$F:$F,"*"&A7&"*",'Scopus review'!$R:$R,"yes") | C7: =COUNTIFS('Scopus review'!$F:$F,"*"&A7&"*",'Scopus review'!$R:$R,"no") | D7: =B7+C7
A8: Silvia Pennino | B8: =COUNTIFS('Scopus review'!$F:$F,"*"&A8&"*",'Scopus review'!$R:$R,"yes") | C8: =COUNTIFS('Scopus review'!$F:$F,"*"&A8&"*",'Scopus review'!$R:$R,"no") | D8: =B8+C8
